  package ExceptionHandling;

import java.io.BufferedReader;
import java.io.InputStreamReader;

class Divide {
	int num1, num2;
	Divide(int num1, int num2){
		this.num1=num1;
		this.num2=num2;
		}
	
	void getDivision() throws ArithmeticException {
		int div = num1/num2;
		throw new ArithmeticException();
	//System.out.println("Division of 2 number is =%d".formatted(div));
//		try {
//			int div = num1/num2;
//			System.out.println("Division of 2 number is =%d".formatted(div));
//		}catch(Exception ae) {
//			System.out.println("Please insert none zero value");
//		}
		
		//System.out.println("This line is after division result");
	}
}
public class DividebyZeroExceptionEx {

	public static void main(String[] args)  {
		// TODO Auto-generated method stub
		BufferedReader br =new BufferedReader(new InputStreamReader(System.in));
		br.readLine();
		System.out.println("This line is in starting of main method");
            Divide d =new Divide(122,0);
            d.getDivision();
            System.out.println("This line is after division result in main method");
	}

}
